Workbook

Sheet Dashboard & Global Settings
A1: Executive Dashboard & Global Settings
A2: Portfolio-level controls, KPIs, charts, and dorm-level filtering.
A3: Global Controls
A4: Current Month | B4: 46023
A5: Current Year | B5: 2026
A6: Dorm Filter | B6: All Dorms
A8: Revenue | B8: Total Portfolio Revenue
A9: Revenue | B9: Revenue This Month
A10: Revenue | B10: Revenue YTD | C10: =SUMPRODUCT((FinancialModel[Month]>=DATE(CurrentYear,1,1))*(FinancialModel[Month]<=EOMONTH(DATE(CurrentYear,MONTH(CurrentMonth),1),0))*(FinancialModel[Actual Revenue])*(IF(SelectedDorm="All Dorms",1,--(FinancialModel[[#This Row],[Dorm Name]]=SelectedDorm))))
A11: Expenses | B11: Total Operating Expenses | C11: =SUMPRODUCT((FinancialModel[Month]=DATE(CurrentYear,MONTH(CurrentMonth),1))*(FinancialModel[Operating Expenses])*(IF(SelectedDorm="All Dorms",1,--(FinancialModel[[#This Row],[Dorm Name]]=SelectedDorm))))
A12: Expenses | B12: Electricity Expenses | C12: =SUMPRODUCT((RoomElectricity[Month]=DATE(CurrentYear,MONTH(CurrentMonth),1))*(RoomElectricity[Total Room Electricity])*(IF(SelectedDorm="All Dorms",1,--(RoomElectricity[Dorm]=SelectedDorm))))+SUMPRODUCT(('Electricity Management'!$B$6:$B$300=DATE(CurrentYear,MONTH(CurrentMonth),1))*(CommonElectricity[Common Area Cost])*(IF(SelectedDorm="All Dorms",1,--(CommonElectricity[Dorm]=SelectedDorm))))
A13: Expenses | B13: Renovation Expenses | C13: =IF(SelectedDorm="All Dorms",SUM(RenovationTracker[Actual Cost]),SUMIFS(RenovationTracker[Actual Cost],RenovationTracker[Dorm Name],SelectedDorm))
A14: Expenses | B14: Rental Expenses | C14: =SUMPRODUCT((FinancialModel[Month]=DATE(CurrentYear,MONTH(CurrentMonth),1))*(FinancialModel[Building Rent])*(IF(SelectedDorm="All Dorms",1,--(FinancialModel[[#This Row],[Dorm Name]]=SelectedDorm))))
A15: Profitability | B15: Net Profit | C15: =C9-C11-C12
A16: Profitability | B16: Net Margin % | C16: =IFERROR(C15/C9,0)
A17: Occupancy | B17: Total Beds | C17: =IF(SelectedDorm="All Dorms",SUM(DormRegistry[Bed Capacity]),IFERROR(_xlfn.XLOOKUP(SelectedDorm,DormRegistry[Dorm Name],DormRegistry[Bed Capacity]),0))
A18: Occupancy | B18: Occupied Beds
A19: Occupancy | B19: Available Beds | C19: =C17-C18
A20: Occupancy | B20: Occupancy % | C20: =IFERROR(C18/C17,0)
A36: Month | B36: Revenue Trend | C36: Expense Trend | D36: Occupancy % | F36: Dorm | G36: Revenue
A37: =EDATE(DATE(CurrentYear,MONTH(CurrentMonth),1),-11) | B37: =SUMPRODUCT((FinancialModel[Month]=A37)*(FinancialModel[Actual Revenue])*(IF(SelectedDorm="All Dorms",1,--(FinancialModel[[#This Row],[Dorm Name]]=SelectedDorm)))) | C37: =SUMPRODUCT((FinancialModel[Month]=A37)*(FinancialModel[Operating Expenses])*(IF(SelectedDorm="All Dorms",1,--(FinancialModel[[#This Row],[Dorm Name]]=SelectedDorm)))) | F37: Dorm 1 | G37: =SUMIFS(FinancialModel[Actual Revenue],FinancialModel[Dorm Name],F37)
A38: =EDATE(DATE(CurrentYear,MONTH(CurrentMonth),1),-10) | B38: =SUMPRODUCT((FinancialModel[Month]=A38)*(FinancialModel[Actual Revenue])*(IF(SelectedDorm="All Dorms",1,--(FinancialModel[[#This Row],[Dorm Name]]=SelectedDorm)))) | C38: =SUMPRODUCT((FinancialModel[Month]=A38)*(FinancialModel[Operating Expenses])*(IF(SelectedDorm="All Dorms",1,--(FinancialModel[[#This Row],[Dorm Name]]=SelectedDorm)))) | F38: Dorm 2 | G38: =SUMIFS(FinancialModel[Actual Revenue],FinancialModel[Dorm Name],F38)
A39: =EDATE(DATE(CurrentYear,MONTH(CurrentMonth),1),-9) | B39: =SUMPRODUCT((FinancialModel[Month]=A39)*(FinancialModel[Actual Revenue])*(IF(SelectedDorm="All Dorms",1,--(FinancialModel[[#This Row],[Dorm Name]]=SelectedDorm)))) | C39: =SUMPRODUCT((FinancialModel[Month]=A39)*(FinancialModel[Operating Expenses])*(IF(SelectedDorm="All Dorms",1,--(FinancialModel[[#This Row],[Dorm Name]]=SelectedDorm)))) | F39: Dorm 3 | G39: =SUMIFS(FinancialModel[Actual Revenue],FinancialModel[Dorm Name],F39)
A40: =EDATE(DATE(CurrentYear,MONTH(CurrentMonth),1),-8) | B40: =SUMPRODUCT((FinancialModel[Month]=A40)*(FinancialModel[Actual Revenue])*(IF(SelectedDorm="All Dorms",1,--(FinancialModel[[#This Row],[Dorm Name]]=SelectedDorm)))) | C40: =SUMPRODUCT((FinancialModel[Month]=A40)*(FinancialModel[Operating Expenses])*(IF(SelectedDorm="All Dorms",1,--(FinancialModel[[#This Row],[Dorm Name]]=SelectedDorm))))
A41: =EDATE(DATE(CurrentYear,MONTH(CurrentMonth),1),-7) | B41: =SUMPRODUCT((FinancialModel[Month]=A41)*(FinancialModel[Actual Revenue])*(IF(SelectedDorm="All Dorms",1,--(FinancialModel[[#This Row],[Dorm Name]]=SelectedDorm)))) | C41: =SUMPRODUCT((FinancialModel[Month]=A41)*(FinancialModel[Operating Expenses])*(IF(SelectedDorm="All Dorms",1,--(FinancialModel[[#This Row],[Dorm Name]]=SelectedDorm))))
A42: =EDATE(DATE(CurrentYear,MONTH(CurrentMonth),1),-6) | B42: =SUMPRODUCT((FinancialModel[Month]=A42)*(FinancialModel[Actual Revenue])*(IF(SelectedDorm="All Dorms",1,--(FinancialModel[[#This Row],[Dorm Name]]=SelectedDorm)))) | C42: =SUMPRODUCT((FinancialModel[Month]=A42)*(FinancialModel[Operating Expenses])*(IF(SelectedDorm="All Dorms",1,--(FinancialModel[[#This Row],[Dorm Name]]=SelectedDorm))))
A43: =EDATE(DATE(CurrentYear,MONTH(CurrentMonth),1),-5) | B43: =SUMPRODUCT((FinancialModel[Month]=A43)*(FinancialModel[Actual Revenue])*(IF(SelectedDorm="All Dorms",1,--(FinancialModel[[#This Row],[Dorm Name]]=SelectedDorm)))) | C43: =SUMPRODUCT((FinancialModel[Month]=A43)*(FinancialModel[Operating Expenses])*(IF(SelectedDorm="All Dorms",1,--(FinancialModel[[#This Row],[Dorm Name]]=SelectedDorm))))
A44: =EDATE(DATE(CurrentYear,MONTH(CurrentMonth),1),-4) | B44: =SUMPRODUCT((FinancialModel[Month]=A44)*(FinancialModel[Actual Revenue])*(IF(SelectedDorm="All Dorms",1,--(FinancialModel[[#This Row],[Dorm Name]]=SelectedDorm)))) | C44: =SUMPRODUCT((FinancialModel[Month]=A44)*(FinancialModel[Operating Expenses])*(IF(SelectedDorm="All Dorms",1,--(FinancialModel[[#This Row],[Dorm Name]]=SelectedDorm))))
A45: =EDATE(DATE(CurrentYear,MONTH(CurrentMonth),1),-3) | B45: =SUMPRODUCT((FinancialModel[Month]=A45)*(FinancialModel[Actual Revenue])*(IF(SelectedDorm="All Dorms",1,--(FinancialModel[[#This Row],[Dorm Name]]=SelectedDorm)))) | C45: =SUMPRODUCT((FinancialModel[Month]=A45)*(FinancialModel[Operating Expenses])*(IF(SelectedDorm="All Dorms",1,--(FinancialModel[[#This Row],[Dorm Name]]=SelectedDorm))))
A46: =EDATE(DATE(CurrentYear,MONTH(CurrentMonth),1),-2) | B46: =SUMPRODUCT((FinancialModel[Month]=A46)*(FinancialModel[Actual Revenue])*(IF(SelectedDorm="All Dorms",1,--(FinancialModel[[#This Row],[Dorm Name]]=SelectedDorm)))) | C46: =SUMPRODUCT((FinancialModel[Month]=A46)*(FinancialModel[Operating Expenses])*(IF(SelectedDorm="All Dorms",1,--(FinancialModel[[#This Row],[Dorm Name]]=SelectedDorm))))
A47: =EDATE(DATE(CurrentYear,MONTH(CurrentMonth),1),-1) | B47: =SUMPRODUCT((FinancialModel[Month]=A47)*(FinancialModel[Actual Revenue])*(IF(SelectedDorm="All Dorms",1,--(FinancialModel[[#This Row],[Dorm Name]]=SelectedDorm)))) | C47: =SUMPRODUCT((FinancialModel[Month]=A47)*(FinancialModel[Operating Expenses])*(IF(SelectedDorm="All Dorms",1,--(FinancialModel[[#This Row],[Dorm Name]]=SelectedDorm))))
A48: =EDATE(DATE(CurrentYear,MONTH(CurrentMonth),1),0) | B48: =SUMPRODUCT((FinancialModel[Month]=A48)*(FinancialModel[Actual Revenue])*(IF(SelectedDorm="All Dorms",1,--(FinancialModel[[#This Row],[Dorm Name]]=SelectedDorm)))) | C48: =SUMPRODUCT((FinancialModel[Month]=A48)*(FinancialModel[Operating Expenses])*(IF(SelectedDorm="All Dorms",1,--(FinancialModel[[#This Row],[Dorm Name]]=SelectedDorm))))

Sheet Renovation & Projects
A1: Dorm Renovation & Project Tracker
A2: Budget, contractor, completion, and variance tracker for projects.
A4: Total Budget | B4: =SUM(RenovationTracker[Estimated Budget])
A5: Total Spent | B5: =SUM(RenovationTracker[Actual Cost])
A6: Remaining Budget | B6: =B5-B6
A7: Completion % | B7: =IFERROR(COUNTIF(RenovationTracker[Payment Status],"Paid")/COUNTA(RenovationTracker[Category]),0)
A10: Dorm Name | B10: Category | C10: Estimated Budget | D10: Actual Cost | E10: Variance | F10: Variance % | G10: Payment Status | H10: Contractor Name | I10: Contractor Phone | J10: Completion Date | K10: Notes
A11: Dorm 2 | B11: Painting | C11: 10 | D11: 15 | E11: =D11-C11 | F11: =IFERROR(E11/C11,0) | G11: Unpaid
A12: Dorm 2 | B12: Beds & Mattresses | C12: 0 | D12: 0 | E12: =D12-C12 | F12: =IFERROR(E12/C12,0) | G12: Unpaid
A13: Dorm 2 | B13: Kitchen Appliances | C13: 0 | D13: 0 | E13: =D13-C13 | F13: =IFERROR(E13/C13,0) | G13: Unpaid
A14: Dorm 2 | B14: Plumbing | C14: 0 | D14: 0 | E14: =D14-C14 | F14: =IFERROR(E14/C14,0) | G14: Unpaid
A15: Dorm 2 | B15: Furniture | C15: 0 | D15: 0 | E15: =D15-C15 | F15: =IFERROR(E15/C15,0) | G15: Unpaid
A16: Dorm 2 | B16: Electricity & Wiring | C16: 0 | D16: 0 | E16: =D16-C16 | F16: =IFERROR(E16/C16,0) | G16: Unpaid
A17: Dorm 2 | B17: CCTV Installation | C17: 0 | D17: 0 | E17: =D17-C17 | F17: =IFERROR(E17/C17,0) | G17: Unpaid
A18: Dorm 2 | B18: Internet Infrastructure | C18: 0 | D18: 0 | E18: =D18-C18 | F18: =IFERROR(E18/C18,0) | G18: Unpaid
A19: Dorm 2 | B19: Curtains & Decorations | C19: 0 | D19: 0 | E19: =D19-C19 | F19: =IFERROR(E19/C19,0) | G19: Unpaid
A20: Dorm 2 | B20: Cleaning Equipment | C20: 0 | D20: 0 | E20: =D20-C20 | F20: =IFERROR(E20/C20,0) | G20: Unpaid
A21: Dorm 2 | B21: Contingency / Miscellaneous | C21: 0 | D21: 0 | E21: =D21-C21 | F21: =IFERROR(E21/C21,0) | G21: Unpaid
E22: =D22-C22 | F22: =IFERROR(E22/C22,0)
E23: =D23-C23 | F23: =IFERROR(E23/C23,0)
E24: =D24-C24 | F24: =IFERROR(E24/C24,0)
E25: =D25-C25 | F25: =IFERROR(E25/C25,0)
E26: =D26-C26 | F26: =IFERROR(E26/C26,0)
E27: =D27-C27 | F27: =IFERROR(E27/C27,0)
E28: =D28-C28 | F28: =IFERROR(E28/C28,0)
E29: =D29-C29 | F29: =IFERROR(E29/C29,0)
E30: =D30-C30 | F30: =IFERROR(E30/C30,0)
E31: =D31-C31 | F31: =IFERROR(E31/C31,0)
E32: =D32-C32 | F32: =IFERROR(E32/C32,0)
E33: =D33-C33 | F33: =IFERROR(E33/C33,0)
... E200: =D200-C200 | F200: =IFERROR(E200/C200,0)

Sheet Client DB & Bed Mgmt
A1: Client Database & Bed Management
A2: Each row represents one bed. Use Dorm / Building for the property and Client Name for the person.
A3: IMPORTANT: Column A = Dorm / Building (Dorm 1, Dorm 2, Dorm 3). Column D = Client Name. Then use Room Number and Bed ID for the bed assignment.
A4: Dorm / Building | B4: Room Number | C4: Bed ID | D4: Client Name | E4: Status | F4: Entire Room Rental | G4: Monthly Rent | H4: Room Occupied Beds | I4: rent/moth | J4: Electricity Per Person | K4: Common Area Per Person | L4: Payment Status | M4: Move-in Date | N4: Move-out Date | O4: Security Deposit | P4: ID / Passport Number | Q4: Phone Number | R4: Emergency Contact | S4: Contract End Date | T4: Invoice Unit
A5: Dorm 1 | B5: Room 1-1 | C5: Dorm1-R1A | D5: ikr | E5: =IF(D5<>"","Occupied","Vacant") | F5: =IF(COUNTIFS($B:$B,B5,$E:$E,"Occupied")=2,"Yes","No") | G5: =DefaultRentPerBed | H5: =IF(E5<>"Occupied",0,COUNTIFS($B:$B,B5,$E:$E,"Occupied")) | I5: =IF(E5<>"Occupied",0,IF(H5=1,350,IF(H5=2,200,0))) | J5: =IF(E5="Occupied",IFERROR(SUMIFS('Electricity Management'!$J:$J,'Electricity Management'!$A:$A,A5,'Electricity Management'!$C:$C,B5),0),0) | K5: {=IF(E5="Occupied",IFERROR(INDEX('Electricity Management'!$T:$T,MATCH(1,('Electricity Management'!$K:$K=A5)*('Electricity Management'!$L:$L=B5),0)),0),"")} | L5: Partially Paid | M5: 46296 | N5: 46376 | Q5: 0657202020 | T5: =IF(F5="Yes",A5&"-"&B5,C5)
A6: Dorm 1 | B6: Room 1-1 | C6: Dorm1-R1B | D6: vrr | E6: =IF(D6<>"","Occupied","Vacant") | F6: =IF(COUNTIFS($B:$B,B6,$E:$E,"Occupied")=2,"Yes","No") | G6: =DefaultRentPerBed | H6: =IF(E6<>"Occupied",0,COUNTIFS($B:$B,B6,$E:$E,"Occupied")) | I6: =IF(E6<>"Occupied",0,IF(H6=1,350,IF(H6=2,200,0))) | J6: =IF(E6="Occupied",IFERROR(SUMIFS('Electricity Management'!$J:$J,'Electricity Management'!$A:$A,A6,'Electricity Management'!$C:$C,B6),0),0) | K6: {=IF(E6="Occupied",IFERROR(INDEX('Electricity Management'!$T:$T,MATCH(1,('Electricity Management'!$K:$K=A6)*('Electricity Management'!$L:$L=B6),0)),0),"")} | L6: unpaid | M6: 46297 | N6: 30 juin | T6: =IF(F6="Yes",A6&"-"&B6,C6)
A7: Dorm 1 | B7: Room 1-2 | C7: Dorm1-R2B | D7: vv | E7: =IF(D7<>"","Occupied","Vacant") | F7: =IF(COUNTIFS($B:$B,B7,$E:$E,"Occupied")=2,"Yes","No") | G7: =DefaultRentPerBed | H7: =IF(E7<>"Occupied",0,COUNTIFS($B:$B,B7,$E:$E,"Occupied")) | I7: =IF(E7<>"Occupied",0,IF(H7=1,350,IF(H7=2,200,0))) | J7: =IF(E7="Occupied",IFERROR(SUMIFS('Electricity Management'!$J:$J,'Electricity Management'!$A:$A,A7,'Electricity Management'!$C:$C,B7),0),0) | K7: {=IF(E7="Occupied",IFERROR(INDEX('Electricity Management'!$T:$T,MATCH(1,('Electricity Management'!$K:$K=A7)*('Electricity Management'!$L:$L=B7),0)),0),"")} | L7: Partially Paid | M7: 46298 | T7: =IF(F7="Yes",A7&"-"&B7,C7)
A8: Dorm 1 | B8: Room 1-2 | C8: Dorm1-R2C | E8: =IF(D8<>"","Occupied","Vacant") | F8: =IF(COUNTIFS($B:$B,B8,$E:$E,"Occupied")=2,"Yes","No") | G8: =DefaultRentPerBed | H8: =IF(E8<>"Occupied",0,COUNTIFS($B:$B,B8,$E:$E,"Occupied")) | I8: =IF(E8<>"Occupied",0,IF(H8=1,350,IF(H8=2,200,0))) | J8: =IF(E8="Occupied",IFERROR(SUMIFS('Electricity Management'!$J:$J,'Electricity Management'!$A:$A,A8,'Electricity Management'!$C:$C,B8),0),0) | K8: {=IF(E8="Occupied",IFERROR(INDEX('Electricity Management'!$T:$T,MATCH(1,('Electricity Management'!$K:$K=A8)*('Electricity Management'!$L:$L=B8),0)),0),"")} | T8: =IF(F8="Yes",A8&"-"&B8,C8)
A9: Dorm 1 | B9: Room 1-3 | C9: Dorm1-R3A | E9: =IF(D9<>"","Occupied","Vacant") | F9: =IF(COUNTIFS($B:$B,B9,$E:$E,"Occupied")=2,"Yes","No") | G9: =DefaultRentPerBed | H9: =IF(E9<>"Occupied",0,COUNTIFS($B:$B,B9,$E:$E,"Occupied")) | I9: =IF(E9<>"Occupied",0,IF(H9=1,350,IF(H9=2,200,0))) | J9: =IF(E9="Occupied",IFERROR(SUMIFS('Electricity Management'!$J:$J,'Electricity Management'!$A:$A,A9,'Electricity Management'!$C:$C,B9),0),0) | K9: {=IF(E9="Occupied",IFERROR(INDEX('Electricity Management'!$T:$T,MATCH(1,('Electricity Management'!$K:$K=A9)*('Electricity Management'!$L:$L=B9),0)),0),"")} | T9: =IF(F9="Yes",A9&"-"&B9,C9)
A10: Dorm 1 | B10: Room 1-3 | C10: Dorm1-R3B | E10: =IF(D10<>"","Occupied","Vacant") | F10: =IF(COUNTIFS($B:$B,B10,$E:$E,"Occupied")=2,"Yes","No") | G10: =DefaultRentPerBed | H10: =IF(E10<>"Occupied",0,COUNTIFS($B:$B,B10,$E:$E,"Occupied")) | I10: =IF(E10<>"Occupied",0,IF(H10=1,350,IF(H10=2,200,0))) | J10: =IF(E10="Occupied",IFERROR(SUMIFS('Electricity Management'!$J:$J,'Electricity Management'!$A:$A,A10,'Electricity Management'!$C:$C,B10),0),0) | K10: {=IF(E10="Occupied",IFERROR(INDEX('Electricity Management'!$T:$T,MATCH(1,('Electricity Management'!$K:$K=A10)*('Electricity Management'!$L:$L=B10),0)),0),"")} | T10: =IF(F10="Yes",A10&"-"&B10,C10)
A11: Dorm 1 | B11: Room 1-4 | C11: Dorm1-R4A | E11: =IF(D11<>"","Occupied","Vacant") | F11: =IF(COUNTIFS($B:$B,B11,$E:$E,"Occupied")=2,"Yes","No") | G11: =DefaultRentPerBed | H11: =IF(E11<>"Occupied",0,COUNTIFS($B:$B,B11,$E:$E,"Occupied")) | I11: =IF(E11<>"Occupied",0,IF(H11=1,350,IF(H11=2,200,0))) | J11: =IF(E11="Occupied",IFERROR(SUMIFS('Electricity Management'!$J:$J,'Electricity Management'!$A:$A,A11,'Electricity Management'!$C:$C,B11),0),0) | K11: {=IF(E11="Occupied",IFERROR(INDEX('Electricity Management'!$T:$T,MATCH(1,('Electricity Management'!$K:$K=A11)*('Electricity Management'!$L:$L=B11),0)),0),"")} | T11: =IF(F11="Yes",A11&"-"&B11,C11)
A12: Dorm 1 | B12: Room 1-4 | C12: Dorm1-R4B | E12: =IF(D12<>"","Occupied","Vacant") | F12: =IF(COUNTIFS($B:$B,B12,$E:$E,"Occupied")=2,"Yes","No") | G12: =DefaultRentPerBed | H12: =IF(E12<>"Occupied",0,COUNTIFS($B:$B,B12,$E:$E,"Occupied")) | I12: =IF(E12<>"Occupied",0,IF(H12=1,350,IF(H12=2,200,0))) | J12: =IF(E12="Occupied",IFERROR(SUMIFS('Electricity Management'!$J:$J,'Electricity Management'!$A:$A,A12,'Electricity Management'!$C:$C,B12),0),0) | K12: {=IF(E12="Occupied",IFERROR(INDEX('Electricity Management'!$T:$T,MATCH(1,('Electricity Management'!$K:$K=A12)*('Electricity Management'!$L:$L=B12),0)),0),"")} | T12: =IF(F12="Yes",A12&"-"&B12,C12)
A13: Dorm 1 | B13: Room 1-5 | C13: Dorm1-R5A | E13: =IF(D13<>"","Occupied","Vacant") | F13: =IF(COUNTIFS($B:$B,B13,$E:$E,"Occupied")=2,"Yes","No") | G13: =DefaultRentPerBed | H13: =IF(E13<>"Occupied",0,COUNTIFS($B:$B,B13,$E:$E,"Occupied")) | I13: =IF(E13<>"Occupied",0,IF(H13=1,350,IF(H13=2,200,0))) | J13: =IF(E13="Occupied",IFERROR(SUMIFS('Electricity Management'!$J:$J,'Electricity Management'!$A:$A,A13,'Electricity Management'!$C:$C,B13),0),0) | K13: {=IF(E13="Occupied",IFERROR(INDEX('Electricity Management'!$T:$T,MATCH(1,('Electricity Management'!$K:$K=A13)*('Electricity Management'!$L:$L=B13),0)),0),"")} | T13: =IF(F13="Yes",A13&"-"&B13,C13)
A14: Dorm 1 | B14: Room 1-5 | C14: Dorm1-R5B | E14: =IF(D14<>"","Occupied","Vacant") | F14: =IF(COUNTIFS($B:$B,B14,$E:$E,"Occupied")=2,"Yes","No") | G14: =DefaultRentPerBed | H14: =IF(E14<>"Occupied",0,COUNTIFS($B:$B,B14,$E:$E,"Occupied")) | I14: =IF(E14<>"Occupied",0,IF(H14=1,350,IF(H14=2,200,0))) | J14: =IF(E14="Occupied",IFERROR(SUMIFS('Electricity Management'!$J:$J,'Electricity Management'!$A:$A,A14,'Electricity Management'!$C:$C,B14),0),0) | K14: {=IF(E14="Occupied",IFERROR(INDEX('Electricity Management'!$T:$T,MATCH(1,('Electricity Management'!$K:$K=A14)*('Electricity Management'!$L:$L=B14),0)),0),"")} | T14: =IF(F14="Yes",A14&"-"&B14,C14)
A15: Dorm 1 | B15: Room 1-6 | C15: Dorm1-R6A | E15: =IF(D15<>"","Occupied","Vacant") | F15: =IF(COUNTIFS($B:$B,B15,$E:$E,"Occupied")=2,"Yes","No") | G15: =DefaultRentPerBed | H15: =IF(E15<>"Occupied",0,COUNTIFS($B:$B,B15,$E:$E,"Occupied")) | I15: =IF(E15<>"Occupied",0,IF(H15=1,350,IF(H15=2,200,0))) | J15: =IF(E15="Occupied",IFERROR(SUMIFS('Electricity Management'!$J:$J,'Electricity Management'!$A:$A,A15,'Electricity Management'!$C:$C,B15),0),0) | K15: {=IF(E15="Occupied",IFERROR(INDEX('Electricity Management'!$T:$T,MATCH(1,('Electricity Management'!$K:$K=A15)*('Electricity Management'!$L:$L=B15),0)),0),"")} | T15: =IF(F15="Yes",A15&"-"&B15,C15)
A16: Dorm 1 | B16: Room 1-6 | C16: Dorm1-R6B | E16: =IF(D16<>"","Occupied","Vacant") | F16: =IF(COUNTIFS($B:$B,B16,$E:$E,"Occupied")=2,"Yes","No") | G16: =DefaultRentPerBed | H16: =IF(E16<>"Occupied",0,COUNTIFS($B:$B,B16,$E:$E,"Occupied")) | I16: =IF(E16<>"Occupied",0,IF(H16=1,350,IF(H16=2,200,0))) | J16: =IF(E16="Occupied",IFERROR(SUMIFS('Electricity Management'!$J:$J,'Electricity Management'!$A:$A,A16,'Electricity Management'!$C:$C,B16),0),0) | K16: {=IF(E16="Occupied",IFERROR(INDEX('Electricity Management'!$T:$T,MATCH(1,('Electricity Management'!$K:$K=A16)*('Electricity Management'!$L:$L=B16),0)),0),"")} | T16: =IF(F16="Yes",A16&"-"&B16,C16)
A17: Dorm 2 | B17: Room 2-1 | C17: Dorm2-R1A | E17: =IF(D17<>"","Occupied","Vacant") | F17: =IF(COUNTIFS($B:$B,B17,$E:$E,"Occupied")=2,"Yes","No") | G17: =DefaultRentPerBed | H17: =IF(E17<>"Occupied",0,COUNTIFS($B:$B,B17,$E:$E,"Occupied")) | I17: =IF(E17<>"Occupied",0,IF(H17=1,350,IF(H17=2,200,0))) | J17: =IF(E17="Occupied",IFERROR(SUMIFS('Electricity Management'!$J:$J,'Electricity Management'!$A:$A,A17,'Electricity Management'!$C:$C,B17),0),0) | K17: {=IF(E17="Occupied",IFERROR(INDEX('Electricity Management'!$T:$T,MATCH(1,('Electricity Management'!$K:$K=A17)*('Electricity Management'!$L:$L=B17),0)),0),"")} | T17: =IF(F17="Yes",A17&"-"&B17,C17)
A18: Dorm 2 | B18: Room 2-1 | C18: Dorm2-R1B | E18: =IF(D18<>"","Occupied","Vacant") | F18: =IF(COUNTIFS($B:$B,B18,$E:$E,"Occupied")=2,"Yes","No") | G18: =DefaultRentPerBed | H18: =IF(E18<>"Occupied",0,COUNTIFS($B:$B,B18,$E:$E,"Occupied")) | I18: =IF(E18<>"Occupied",0,IF(H18=1,350,IF(H18=2,200,0))) | J18: =IF(E18="Occupied",IFERROR(SUMIFS('Electricity Management'!$J:$J,'Electricity Management'!$A:$A,A18,'Electricity Management'!$C:$C,B18),0),0) | K18: {=IF(E18="Occupied",IFERROR(INDEX('Electricity Management'!$T:$T,MATCH(1,('Electricity Management'!$K:$K=A18)*('Electricity Management'!$L:$L=B18),0)),0),"")} | T18: =IF(F18="Yes",A18&"-"&B18,C18)
A19: Dorm 2 | B19: Room 2-2 | C19: Dorm2-R2A | E19: =IF(D19<>"","Occupied","Vacant") | F19: =IF(COUNTIFS($B:$B,B19,$E:$E,"Occupied")=2,"Yes","No") | G19: =DefaultRentPerBed | H19: =IF(E19<>"Occupied",0,COUNTIFS($B:$B,B19,$E:$E,"Occupied")) | I19: =IF(E19<>"Occupied",0,IF(H19=1,350,IF(H19=2,200,0))) | J19: =IF(E19="Occupied",IFERROR(SUMIFS('Electricity Management'!$J:$J,'Electricity Management'!$A:$A,A19,'Electricity Management'!$C:$C,B19),0),0) | K19: {=IF(E19="Occupied",IFERROR(INDEX('Electricity Management'!$T:$T,MATCH(1,('Electricity Management'!$K:$K=A19)*('Electricity Management'!$L:$L=B19),0)),0),"")} | T19: =IF(F19="Yes",A19&"-"&B19,C19)
... A35: Dorm 3 | B35: Room 3-4 | C35: Dorm3-R4A | E35: =IF(D35<>"","Occupied","Vacant") | F35: =IF(COUNTIFS($B:$B,B35,$E:$E,"Occupied")=2,"Yes","No") | G35: =DefaultRentPerBed | H35: =IF(E35<>"Occupied",0,COUNTIFS($B:$B,B35,$E:$E,"Occupied")) | I35: =IF(E35<>"Occupied",0,IF(H35=1,350,IF(H35=2,200,0))) | J35: =IF(E35="Occupied",IFERROR(SUMIFS('Electricity Management'!$J:$J,'Electricity Management'!$A:$A,A35,'Electricity Management'!$C:$C,B35),0),0) | K35: {=IF(E35="Occupied",IFERROR(INDEX('Electricity Management'!$T:$T,MATCH(1,('Electricity Management'!$K:$K=A35)*('Electricity Management'!$L:$L=B35),0)),0),"")} | T35: =IF(F35="Yes",A35&"-"&B35,C35)
A36: Dorm 3 | B36: Room 3-4 | C36: Dorm3-R4B | E36: =IF(D36<>"","Occupied","Vacant") | F36: =IF(COUNTIFS($B:$B,B36,$E:$E,"Occupied")=2,"Yes","No") | G36: =DefaultRentPerBed | H36: =COUNTIFS($B:$B,B36,$E:$E,"Occupied") | I36: =IF(E36<>"Occupied",0,IF(H36=1,350,IF(H36=2,200,0))) | J36: =IF(E36="Occupied",IFERROR(SUMIFS('Electricity Management'!$J:$J,'Electricity Management'!$A:$A,A36,'Electricity Management'!$C:$C,B36),0),0) | K36: {=IF(E36="Occupied",IFERROR(INDEX('Electricity Management'!$T:$T,MATCH(1,('Electricity Management'!$K:$K=A36)*('Electricity Management'!$L:$L=B36),0)),0),"")} | T36: =IF(F36="Yes",A36&"-"&B36,C36)
A37: Dorm 3 | B37: Room 3-5 | C37: Dorm3-R5A | E37: =IF(D37<>"","Occupied","Vacant") | F37: =IF(COUNTIFS($B:$B,B37,$E:$E,"Occupied")=2,"Yes","No") | G37: =DefaultRentPerBed | H37: =COUNTIFS($B:$B,B37,$E:$E,"Occupied") | I37: =IF(E37<>"Occupied",0,IF(H37=1,350,IF(H37=2,200,0))) | J37: =IF(E37="Occupied",IFERROR(SUMIFS('Electricity Management'!$J:$J,'Electricity Management'!$A:$A,A37,'Electricity Management'!$C:$C,B37),0),0) | K37: {=IF(E37="Occupied",IFERROR(INDEX('Electricity Management'!$T:$T,MATCH(1,('Electricity Management'!$K:$K=A37)*('Electricity Management'!$L:$L=B37),0)),0),"")} | T37: =IF(F37="Yes",A37&"-"&B37,C37)
A38: Dorm 3 | B38: Room 3-5 | C38: Dorm3-R5B | E38: =IF(D38<>"","Occupied","Vacant") | F38: =IF(COUNTIFS($B:$B,B38,$E:$E,"Occupied")=2,"Yes","No") | G38: =DefaultRentPerBed | H38: =COUNTIFS($B:$B,B38,$E:$E,"Occupied") | I38: =IF(E38<>"Occupied",0,IF(H38=1,350,IF(H38=2,200,0))) | J38: =IF(E38="Occupied",IFERROR(SUMIFS('Electricity Management'!$J:$J,'Electricity Management'!$A:$A,A38,'Electricity Management'!$C:$C,B38),0),0) | K38: {=IF(E38="Occupied",IFERROR(INDEX('Electricity Management'!$T:$T,MATCH(1,('Electricity Management'!$K:$K=A38)*('Electricity Management'!$L:$L=B38),0)),0),"")} | T38: =IF(F38="Yes",A38&"-"&B38,C38)
A39: Dorm 3 | B39: Room 3-6 | C39: Dorm3-R6A | E39: =IF(D39<>"","Occupied","Vacant") | F39: =IF(COUNTIFS($B:$B,B39,$E:$E,"Occupied")=2,"Yes","No") | G39: =DefaultRentPerBed | H39: =COUNTIFS($B:$B,B39,$E:$E,"Occupied") | I39: =IF(E39<>"Occupied",0,IF(H39=1,350,IF(H39=2,200,0))) | J39: =IF(E39="Occupied",IFERROR(SUMIFS('Electricity Management'!$J:$J,'Electricity Management'!$A:$A,A39,'Electricity Management'!$C:$C,B39),0),0) | K39: {=IF(E39="Occupied",IFERROR(INDEX('Electricity Management'!$T:$T,MATCH(1,('Electricity Management'!$K:$K=A39)*('Electricity Management'!$L:$L=B39),0)),0),"")} | T39: =IF(F39="Yes",A39&"-"&B39,C39)
A40: Dorm 3 | B40: Room 3-6 | C40: Dorm3-R6B | E40: =IF(D40<>"","Occupied","Vacant") | F40: =IF(COUNTIFS($B:$B,B40,$E:$E,"Occupied")=2,"Yes","No") | G40: =DefaultRentPerBed | H40: =COUNTIFS($B:$B,B40,$E:$E,"Occupied") | I40: =IF(E40<>"Occupied",0,IF(H40=1,350,IF(H40=2,200,0))) | J40: =IF(E40="Occupied",IFERROR(SUMIFS('Electricity Management'!$J:$J,'Electricity Management'!$A:$A,A40,'Electricity Management'!$C:$C,B40),0),0) | K40: {=IF(E40="Occupied",IFERROR(INDEX('Electricity Management'!$T:$T,MATCH(1,('Electricity Management'!$K:$K=A40)*('Electricity Management'!$L:$L=B40),0)),0),"")} | T40: =IF(F40="Yes",A40&"-"&B40,C40)
E41: =IF(D41<>"","Occupied","Vacant") | H41: =COUNTIFS($B:$B,B41,$E:$E,"Occupied") | I41: =IF(E41<>"Occupied",0,IF(H41=1,350,IF(H41=2,200,0))) | J41: =IF(E41="Occupied",IFERROR(SUMIFS('Electricity Management'!$J:$J,'Electricity Management'!$A:$A,A41,'Electricity Management'!$C:$C,B41),0),0) | K41: {=IF(E41="Occupied",IFERROR(INDEX('Electricity Management'!$T:$T,MATCH(1,('Electricity Management'!$K:$K=A41)*('Electricity Management'!$L:$L=B41),0)),0),"")} | T41: =IF(F41="Yes",A41&"-"&B41,C41)
E42: =IF(D42<>"","Occupied","Vacant") | H42: =COUNTIFS($B:$B,B42,$E:$E,"Occupied") | I42: =IF(E42<>"Occupied",0,IF(H42=1,350,IF(H42=2,200,0))) | J42: =IF(E42="Occupied",IFERROR(SUMIFS('Electricity Management'!$J:$J,'Electricity Management'!$A:$A,A42,'Electricity Management'!$C:$C,B42),0),0) | K42: {=IF(E42="Occupied",IFERROR(INDEX('Electricity Management'!$T:$T,MATCH(1,('Electricity Management'!$K:$K=A42)*('Electricity Management'!$L:$L=B42),0)),0),"")} | T42: =IF(F42="Yes",A42&"-"&B42,C42)
E43: =IF(D43<>"","Occupied","Vacant") | H43: =COUNTIFS($B:$B,B43,$E:$E,"Occupied") | I43: =IF(E43<>"Occupied",0,IF(H43=1,350,IF(H43=2,200,0))) | J43: =IF(E43="Occupied",IFERROR(SUMIFS('Electricity Management'!$J:$J,'Electricity Management'!$A:$A,A43,'Electricity Management'!$C:$C,B43),0),0) | K43: {=IF(E43="Occupied",IFERROR(INDEX('Electricity Management'!$T:$T,MATCH(1,('Electricity Management'!$K:$K=A43)*('Electricity Management'!$L:$L=B43),0)),0),"")} | T43: =IF(F43="Yes",A43&"-"&B43,C43)
E44: =IF(D44<>"","Occupied","Vacant") | H44: =COUNTIFS($B:$B,B44,$E:$E,"Occupied") | I44: =IF(E44<>"Occupied",0,IF(H44=1,350,IF(H44=2,200,0))) | J44: =IF(E44="Occupied",IFERROR(SUMIFS('Electricity Management'!$J:$J,'Electricity Management'!$A:$A,A44,'Electricity Management'!$C:$C,B44),0),0) | K44: {=IF(E44="Occupied",IFERROR(INDEX('Electricity Management'!$T:$T,MATCH(1,('Electricity Management'!$K:$K=A44)*('Electricity Management'!$L:$L=B44),0)),0),"")} | T44: =IF(F44="Yes",A44&"-"&B44,C44)
E45: =IF(D45<>"","Occupied","Vacant") | H45: =COUNTIFS($B:$B,B45,$E:$E,"Occupied") | I45: =IF(E45<>"Occupied",0,IF(H45=1,350,IF(H45=2,200,0))) | J45: =IF(E45="Occupied",IFERROR(SUMIFS('Electricity Management'!$J:$J,'Electricity Management'!$A:$A,A45,'Electricity Management'!$C:$C,B45),0),0) | K45: {=IF(E45="Occupied",IFERROR(INDEX('Electricity Management'!$T:$T,MATCH(1,('Electricity Management'!$K:$K=A45)*('Electricity Management'!$L:$L=B45),0)),0),"")} | T45: =IF(F45="Yes",A45&"-"&B45,C45)
E46: =IF(D46<>"","Occupied","Vacant") | H46: =COUNTIFS($B:$B,B46,$E:$E,"Occupied") | I46: =IF(E46<>"Occupied",0,IF(H46=1,350,IF(H46=2,200,0))) | J46: =IF(E46="Occupied",IFERROR(SUMIFS('Electricity Management'!$J:$J,'Electricity Management'!$A:$A,A46,'Electricity Management'!$C:$C,B46),0),0) | K46: {=IF(E46="Occupied",IFERROR(INDEX('Electricity Management'!$T:$T,MATCH(1,('Electricity Management'!$K:$K=A46)*('Electricity Management'!$L:$L=B46),0)),0),"")} | T46: =IF(F46="Yes",A46&"-"&B46,C46)
E47: =IF(D47<>"","Occupied","Vacant") | H47: =COUNTIFS($B:$B,B47,$E:$E,"Occupied") | I47: =IF(E47<>"Occupied",0,IF(H47=1,350,IF(H47=2,200,0))) | J47: =IF(E47="Occupied",IFERROR(SUMIFS('Electricity Management'!$J:$J,'Electricity Management'!$A:$A,A47,'Electricity Management'!$C:$C,B47),0),0) | K47: {=IF(E47="Occupied",IFERROR(INDEX('Electricity Management'!$T:$T,MATCH(1,('Electricity Management'!$K:$K=A47)*('Electricity Management'!$L:$L=B47),0)),0),"")} | T47: =IF(F47="Yes",A47&"-"&B47,C47)
E48: =IF(D48<>"","Occupied","Vacant") | H48: =COUNTIFS($B:$B,B48,$E:$E,"Occupied") | I48: =IF(E48<>"Occupied",0,IF(H48=1,350,IF(H48=2,200,0))) | J48: =IF(E48="Occupied",IFERROR(SUMIFS('Electricity Management'!$J:$J,'Electricity Management'!$A:$A,A48,'Electricity Management'!$C:$C,B48),0),0) | K48: {=IF(E48="Occupied",IFERROR(INDEX('Electricity Management'!$T:$T,MATCH(1,('Electricity Management'!$K:$K=A48)*('Electricity Management'!$L:$L=B48),0)),0),"")} | T48: =IF(F48="Yes",A48&"-"&B48,C48)
E49: =IF(D49<>"","Occupied","Vacant") | H49: =COUNTIFS($B:$B,B49,$E:$E,"Occupied") | I49: =IF(E49<>"Occupied",0,IF(H49=1,350,IF(H49=2,200,0))) | J49: =IF(E49="Occupied",IFERROR(SUMIFS('Electricity Management'!$J:$J,'Electricity Management'!$A:$A,A49,'Electricity Management'!$C:$C,B49),0),0) | K49: {=IF(E49="Occupied",IFERROR(INDEX('Electricity Management'!$T:$T,MATCH(1,('Electricity Management'!$K:$K=A49)*('Electricity Management'!$L:$L=B49),0)),0),"")} | T49: =IF(F49="Yes",A49&"-"&B49,C49)
E50: =IF(D50<>"","Occupied","Vacant") | H50: =COUNTIFS($B:$B,B50,$E:$E,"Occupied") | I50: =IF(E50<>"Occupied",0,IF(H50=1,350,IF(H50=2,200,0))) | J50: =IF(E50="Occupied",IFERROR(SUMIFS('Electricity Management'!$J:$J,'Electricity Management'!$A:$A,A50,'Electricity Management'!$C:$C,B50),0),0) | K50: {=IF(E50="Occupied",IFERROR(INDEX('Electricity Management'!$T:$T,MATCH(1,('Electricity Management'!$K:$K=A50)*('Electricity Management'!$L:$L=B50),0)),0),"")} | T50: =IF(F50="Yes",A50&"-"&B50,C50)
E51: =IF(D51<>"","Occupied","Vacant") | H51: =COUNTIFS($B:$B,B51,$E:$E,"Occupied") | I51: =IF(E51<>"Occupied",0,IF(H51=1,350,IF(H51=2,200,0))) | J51: =IF(E51="Occupied",IFERROR(SUMIFS('Electricity Management'!$J:$J,'Electricity Management'!$A:$A,A51,'Electricity Management'!$C:$C,B51),0),0) | K51: {=IF(E51="Occupied",IFERROR(INDEX('Electricity Management'!$T:$T,MATCH(1,('Electricity Management'!$K:$K=A51)*('Electricity Management'!$L:$L=B51),0)),0),"")} | T51: =IF(F51="Yes",A51&"-"&B51,C51)
E52: =IF(D52<>"","Occupied","Vacant") | H52: =COUNTIFS($B:$B,B52,$E:$E,"Occupied") | I52: =IF(E52<>"Occupied",0,IF(H52=1,350,IF(H52=2,200,0))) | J52: =IF(E52="Occupied",IFERROR(SUMIFS('Electricity Management'!$J:$J,'Electricity Management'!$A:$A,A52,'Electricity Management'!$C:$C,B52),0),0) | K52: {=IF(E52="Occupied",IFERROR(INDEX('Electricity Management'!$T:$T,MATCH(1,('Electricity Management'!$K:$K=A52)*('Electricity Management'!$L:$L=B52),0)),0),"")} | T52: =IF(F52="Yes",A52&"-"&B52,C52)
... E110: =IF(D110<>"","Occupied","Vacant") | H110: =COUNTIFS($B:$B,B110,$E:$E,"Occupied") | I110: =IF(E110<>"Occupied",0,IF(H110=1,350,IF(H110=2,200,0))) | J110: =IF(E110="Occupied",IFERROR(SUMIFS('Electricity Management'!$J:$J,'Electricity Management'!$A:$A,A110,'Electricity Management'!$C:$C,B110),0),0) | K110: {=IF(E110="Occupied",IFERROR(INDEX('Electricity Management'!$T:$T,MATCH(1,('Electricity Management'!$K:$K=A110)*('Electricity Management'!$L:$L=B110),0)),0),"")} | T110: =IF(F110="Yes",A110&"-"&B110,C110)
E111: =IF(D111<>"","Occupied","Vacant") | H111: =COUNTIFS($B:$B,B111,$E:$E,"Occupied") | I111: =IF(E111<>"Occupied",0,IF(H111=1,350,IF(H111=2,200,0))) | J111: =IF(E111="Occupied",IFERROR(SUMIFS('Electricity Management'!$J:$J,'Electricity Management'!$A:$A,A111,'Electricity Management'!$C:$C,B111),0),0) | K111: =IF(E111="Occupied",IFERROR(SUMIFS('Electricity Management'!$T:$T,'Electricity Management'!$K:$K,A111,'Electricity Management'!$L:$L,B111),0),0) | T111: =IF(F111="Yes",A111&"-"&B111,C111)
E112: =IF(D112<>"","Occupied","Vacant") | H112: =COUNTIFS($B:$B,B112,$E:$E,"Occupied") | I112: =IF(E112<>"Occupied",0,IF(H112=1,350,IF(H112=2,200,0))) | J112: =IF(E112="Occupied",IFERROR(SUMIFS('Electricity Management'!$J:$J,'Electricity Management'!$A:$A,A112,'Electricity Management'!$C:$C,B112),0),0) | K112: =IF(E112="Occupied",IFERROR(SUMIFS('Electricity Management'!$T:$T,'Electricity Management'!$K:$K,A112,'Electricity Management'!$L:$L,B112),0),0) | T112: =IF(F112="Yes",A112&"-"&B112,C112)
...

Sheet Electricity Management
A1: Advanced Electricity Management System
A2: Room, generator, government, and common-area split calculations.
A3: IMPORTANT: Dorm column = Dorm 1 / Dorm 2 / Dorm 3. Do NOT type client names here. Client names stay in Client DB column D.
A4: SECTION A - ROOM ELECTRICITY | K4: SECTION B - COMMON AREA ELECTRICITY | U4: SECTION C - PRORATA FACTURE
A5: Dorm | B5: Month | C5: Room Number | D5: Total Room Meter kWh | E5: Generator kWh Supplied | F5: Government kWh | G5: Generator Charge | H5: Government Charge | I5: Total Room Electricity | J5: elec/ocupaied | K5: Dorm | L5: room | M5: Total Occupied Beds | N5: Common Area Meter kWh | O5: Generator kWh Supplied | P5: Government kWh | Q5: Generator Charge | R5: Government Charge | S5: Common Area Cost | T5: Common Area Per Person | U5: Invoice Month | V5: Client | W5: Dorm | X5: Room | Y5: Prorata Days | Z5: Prorata Factor | AA5: Room Elec Prorata | AB5: Area Elec Prorata
A6: Dorm 1 | B6: 46023 | C6: Room 1-1 | D6: 500 | E6: 0 | F6: =MAX(D6-E6,0) | G6: =E6*GeneratorRate | H6: =F6*GovernmentRate | I6: =G6+H6 | J6: =IFERROR(I6/COUNTIFS('Client DB & Bed Mgmt'!$A:$A,A6,'Client DB & Bed Mgmt'!$B:$B,C6,'Client DB & Bed Mgmt'!$D:$D,"<>"),0) | K6: Dorm 1 | L6: Room 1-1 | M6: =COUNTIFS('Client DB & Bed Mgmt'!$A:$A,$K6,'Client DB & Bed Mgmt'!$B:$B,$L6,'Client DB & Bed Mgmt'!$D:$D,"<>") | N6: 100 | O6: 600 | P6: =MAX(N6-O6,0) | Q6: =O6*GeneratorRate | R6: =P6*GovernmentRate | S6: =Q6+R6 | T6: =IF(M6=0,0,S6/M6) | U6: ='Invoice Generator'!$C$7 | V6: ='Invoice Generator'!$C$6 | W6: ='Invoice Generator'!$C$11 | X6: ='Invoice Generator'!$C$12 | Y6: =IFERROR(MAX(0,MIN(IF(OR('Invoice Generator'!$G$13="",NOT(ISNUMBER('Invoice Generator'!$G$13))),EOMONTH($U$6,0),'Invoice Generator'!$G$13),EOMONTH($U$6,0))-MAX(IF(OR('Invoice Generator'!$G$12="",NOT(ISNUMBER('Invoice Generator'!$G$12))),DATE(YEAR($U$6),MONTH($U$6),1),'Invoice Generator'!$G$12),DATE(YEAR($U$6),MONTH($U$6),1))+1),0) | Z6: =IFERROR($Y$6/DAY(EOMONTH($U$6,0)),0) | AA6: ='Invoice Generator'!$G$19*$Z$6 | AB6: ='Invoice Generator'!$G$20*$Z$6
A7: Dorm 1 | B7: 46023 | C7: Room 1-2 | D7: 0 | E7: 0 | F7: =MAX(D7-E7,0) | G7: =E7*GeneratorRate | H7: =F7*GovernmentRate | I7: =G7+H7 | J7: =IFERROR(I7/COUNTIFS('Client DB & Bed Mgmt'!$A:$A,A7,'Client DB & Bed Mgmt'!$B:$B,C7,'Client DB & Bed Mgmt'!$D:$D,"<>"),0) | K7: Dorm 1 | L7: Room 1-2 | M7: =COUNTIFS('Client DB & Bed Mgmt'!$A:$A,$K7,'Client DB & Bed Mgmt'!$B:$B,$L7,'Client DB & Bed Mgmt'!$D:$D,"<>") | N7: 100 | O7: 455 | P7: =MAX(N7-O7,0) | Q7: =O7*GeneratorRate | R7: =P7*GovernmentRate | S7: =Q7+R7 | T7: =IF(M7=0,0,S7/M7)
A8: Dorm 1 | B8: 46023 | C8: Room 1-3 | D8: 0 | E8: 0 | F8: =MAX(D8-E8,0) | G8: =E8*GeneratorRate | H8: =F8*GovernmentRate | I8: =G8+H8 | J8: =IFERROR(I8/COUNTIFS('Client DB & Bed Mgmt'!$A:$A,A8,'Client DB & Bed Mgmt'!$B:$B,C8,'Client DB & Bed Mgmt'!$D:$D,"<>"),0) | K8: Dorm 1 | L8: Room 1-3 | M8: =COUNTIFS('Client DB & Bed Mgmt'!$A:$A,$K8,'Client DB & Bed Mgmt'!$B:$B,$L8,'Client DB & Bed Mgmt'!$D:$D,"<>") | N8: 0 | O8: 0 | P8: =MAX(N8-O8,0) | Q8: =O8*GeneratorRate | R8: =P8*GovernmentRate | S8: =Q8+R8 | T8: =IF(M8=0,0,S8/M8)
A9: Dorm 1 | B9: 46023 | C9: Room 1-4 | D9: 0 | E9: 0 | F9: =MAX(D9-E9,0) | G9: =E9*GeneratorRate | H9: =F9*GovernmentRate | I9: =G9+H9 | J9: =IFERROR(I9/COUNTIFS('Client DB & Bed Mgmt'!$A:$A,A9,'Client DB & Bed Mgmt'!$B:$B,C9,'Client DB & Bed Mgmt'!$D:$D,"<>"),0) | K9: Dorm 1 | L9: Room 1-4 | M9: =COUNTIFS('Client DB & Bed Mgmt'!$A:$A,$K9,'Client DB & Bed Mgmt'!$B:$B,$L9,'Client DB & Bed Mgmt'!$D:$D,"<>") | N9: 0 | O9: 0 | P9: =MAX(N9-O9,0) | Q9: =O9*GeneratorRate | R9: =P9*GovernmentRate | S9: =Q9+R9 | T9: =IF(M9=0,0,S9/M9)
A10: Dorm 1 | B10: 46023 | C10: Room 1-5 | D10: 0 | E10: 0 | F10: =MAX(D10-E10,0) | G10: =E10*GeneratorRate | H10: =F10*GovernmentRate | I10: =G10+H10 | J10: =IFERROR(I10/COUNTIFS('Client DB & Bed Mgmt'!$A:$A,A10,'Client DB & Bed Mgmt'!$B:$B,C10,'Client DB & Bed Mgmt'!$D:$D,"<>"),0) | K10: Dorm 1 | L10: Room 1-5 | M10: =COUNTIFS('Client DB & Bed Mgmt'!$A:$A,$K10,'Client DB & Bed Mgmt'!$B:$B,$L10,'Client DB & Bed Mgmt'!$D:$D,"<>") | N10: 700 | O10: 0 | P10: =MAX(N10-O10,0) | Q10: =O10*GeneratorRate | R10: =P10*GovernmentRate | S10: =Q10+R10 | T10: =IF(M10=0,0,S10/M10)
A11: Dorm 1 | B11: 46023 | C11: Room 1-6 | D11: 0 | E11: 0 | F11: =MAX(D11-E11,0) | G11: =E11*GeneratorRate | H11: =F11*GovernmentRate | I11: =G11+H11 | J11: =IFERROR(I11/COUNTIFS('Client DB & Bed Mgmt'!$A:$A,A11,'Client DB & Bed Mgmt'!$B:$B,C11,'Client DB & Bed Mgmt'!$D:$D,"<>"),0) | K11: Dorm 1 | L11: Room 1-6 | M11: =COUNTIFS('Client DB & Bed Mgmt'!$A:$A,$K11,'Client DB & Bed Mgmt'!$B:$B,$L11,'Client DB & Bed Mgmt'!$D:$D,"<>") | N11: 0 | O11: 0 | P11: =MAX(N11-O11,0) | Q11: =O11*GeneratorRate | R11: =P11*GovernmentRate | S11: =Q11+R11 | T11: =IF(M11=0,0,S11/M11)
A12: Dorm 1 | B12: 46054 | C12: Room 1-1 | D12: 1550 | E12: 0 | F12: =MAX(D12-E12,0) | G12: =E12*GeneratorRate | H12: =F12*GovernmentRate | I12: =G12+H12 | J12: =IFERROR(I12/COUNTIFS('Client DB & Bed Mgmt'!$A:$A,A12,'Client DB & Bed Mgmt'!$B:$B,C12,'Client DB & Bed Mgmt'!$D:$D,"<>"),0) | K12: Dorm 1 | L12: Room 1-1 | M12: =COUNTIFS('Client DB & Bed Mgmt'!$A:$A,$K12,'Client DB & Bed Mgmt'!$B:$B,$L12,'Client DB & Bed Mgmt'!$D:$D,"<>") | N12: 0 | O12: 0 | P12: =MAX(N12-O12,0) | Q12: =O12*GeneratorRate | R12: =P12*GovernmentRate | S12: =Q12+R12 | T12: =IF(M12=0,0,S12/M12)
A13: Dorm 1 | B13: 46054 | C13: Room 1-2 | D13: 100 | E13: 0 | F13: =MAX(D13-E13,0) | G13: =E13*GeneratorRate | H13: =F13*GovernmentRate | I13: =G13+H13 | J13: =IFERROR(I13/COUNTIFS('Client DB & Bed Mgmt'!$A:$A,A13,'Client DB & Bed Mgmt'!$B:$B,C13,'Client DB & Bed Mgmt'!$D:$D,"<>"),0) | K13: Dorm 1 | L13: Room 1-2 | M13: =COUNTIFS('Client DB & Bed Mgmt'!$A:$A,$K13,'Client DB & Bed Mgmt'!$B:$B,$L13,'Client DB & Bed Mgmt'!$D:$D,"<>") | N13: 0 | O13: 0 | P13: =MAX(N13-O13,0) | Q13: =O13*GeneratorRate | R13: =P13*GovernmentRate | S13: =Q13+R13 | T13: =IF(M13=0,0,S13/M13)
A14: Dorm 1 | B14: 46054 | C14: Room 1-3 | D14: 0 | E14: 0 | F14: =MAX(D14-E14,0) | G14: =E14*GeneratorRate | H14: =F14*GovernmentRate | I14: =G14+H14 | J14: =IFERROR(I14/COUNTIFS('Client DB & Bed Mgmt'!$A:$A,A14,'Client DB & Bed Mgmt'!$B:$B,C14,'Client DB & Bed Mgmt'!$D:$D,"<>"),0) | K14: Dorm 1 | L14: Room 1-3 | M14: =COUNTIFS('Client DB & Bed Mgmt'!$A:$A,$K14,'Client DB & Bed Mgmt'!$B:$B,$L14,'Client DB & Bed Mgmt'!$D:$D,"<>") | N14: 0 | O14: 0 | P14: =MAX(N14-O14,0) | Q14: =O14*GeneratorRate | R14: =P14*GovernmentRate | S14: =Q14+R14 | T14: =IF(M14=0,0,S14/M14)
A15: Dorm 1 | B15: 46054 | C15: Room 1-4 | D15: 0 | E15: 0 | F15: =MAX(D15-E15,0) | G15: =E15*GeneratorRate | H15: =F15*GovernmentRate | I15: =G15+H15 | J15: =IFERROR(I15/COUNTIFS('Client DB & Bed Mgmt'!$A:$A,A15,'Client DB & Bed Mgmt'!$B:$B,C15,'Client DB & Bed Mgmt'!$D:$D,"<>"),0) | K15: Dorm 1 | L15: Room 1-4 | M15: =COUNTIFS('Client DB & Bed Mgmt'!$A:$A,$K15,'Client DB & Bed Mgmt'!$B:$B,$L15,'Client DB & Bed Mgmt'!$D:$D,"<>") | N15: 0 | O15: 0 | P15: =MAX(N15-O15,0) | Q15: =O15*GeneratorRate | R15: =P15*GovernmentRate | S15: =Q15+R15 | T15: =IF(M15=0,0,S15/M15)
A16: Dorm 1 | B16: 46054 | C16: Room 1-5 | D16: 0 | E16: 0 | F16: =MAX(D16-E16,0) | G16: =E16*GeneratorRate | H16: =F16*GovernmentRate | I16: =G16+H16 | J16: =IFERROR(I16/COUNTIFS('Client DB & Bed Mgmt'!$A:$A,A16,'Client DB & Bed Mgmt'!$B:$B,C16,'Client DB & Bed Mgmt'!$D:$D,"<>"),0) | K16: Dorm 1 | L16: Room 1-5 | M16: =COUNTIFS('Client DB & Bed Mgmt'!$A:$A,$K16,'Client DB & Bed Mgmt'!$B:$B,$L16,'Client DB & Bed Mgmt'!$D:$D,"<>") | N16: 0 | O16: 0 | P16: =MAX(N16-O16,0) | Q16: =O16*GeneratorRate | R16: =P16*GovernmentRate | S16: =Q16+R16 | T16: =IF(M16=0,0,S16/M16)
A17: Dorm 1 | B17: 46054 | C17: Room 1-6 | D17: 0 | E17: 0 | F17: =MAX(D17-E17,0) | G17: =E17*GeneratorRate | H17: =F17*GovernmentRate | I17: =G17+H17 | J17: =IFERROR(I17/COUNTIFS('Client DB & Bed Mgmt'!$A:$A,A17,'Client DB & Bed Mgmt'!$B:$B,C17,'Client DB & Bed Mgmt'!$D:$D,"<>"),0) | K17: Dorm 1 | L17: Room 1-6 | M17: =COUNTIFS('Client DB & Bed Mgmt'!$A:$A,$K17,'Client DB & Bed Mgmt'!$B:$B,$L17,'Client DB & Bed Mgmt'!$D:$D,"<>") | N17: 0 | O17: 0 | P17: =MAX(N17-O17,0) | Q17: =O17*GeneratorRate | R17: =P17*GovernmentRate | S17: =Q17+R17 | T17: =IF(M17=0,0,S17/M17)
A18: Dorm 1 | B18: 46082 | C18: Room 1-1 | D18: 0 | E18: 0 | F18: =MAX(D18-E18,0) | G18: =E18*GeneratorRate | H18: =F18*GovernmentRate | I18: =G18+H18 | J18: =IFERROR(I18/COUNTIFS('Client DB & Bed Mgmt'!$A:$A,A18,'Client DB & Bed Mgmt'!$B:$B,C18,'Client DB & Bed Mgmt'!$D:$D,"<>"),0) | K18: Dorm 1 | L18: Room 1-1 | M18: =COUNTIFS('Client DB & Bed Mgmt'!$A:$A,$K18,'Client DB & Bed Mgmt'!$B:$B,$L18,'Client DB & Bed Mgmt'!$D:$D,"<>") | N18: 0 | O18: 0 | P18: =MAX(N18-O18,0) | Q18: =O18*GeneratorRate | R18: =P18*GovernmentRate | S18: =Q18+R18 | T18: =IF(M18=0,0,S18/M18)
... A41: Dorm 1 | B41: 46174 | C41: Room 1-6 | D41: 0 | E41: 0 | F41: =MAX(D41-E41,0) | G41: =E41*GeneratorRate | H41: =F41*GovernmentRate | I41: =G41+H41 | J41: =IFERROR(I41/COUNTIFS('Client DB & Bed Mgmt'!$A:$A,A41,'Client DB & Bed Mgmt'!$B:$B,C41,'Client DB & Bed Mgmt'!$D:$D,"<>"),0) | K41: Dorm 1 | L41: Room 1-6 | M41: =COUNTIFS('Client DB & Bed Mgmt'!$A:$A,$K41,'Client DB & Bed Mgmt'!$B:$B,$L41,'Client DB & Bed Mgmt'!$D:$D,"<>") | N41: 0 | O41: 0 | P41: =MAX(N41-O41,0) | Q41: =O41*GeneratorRate | R41: =P41*GovernmentRate | S41: =Q41+R41 | T41: =IF(M41=0,0,S41/M41)
A42: Dorm 1 | B42: 46204 | C42: Room 1-1 | D42: 0 | E42: 0 | F42: =MAX(D42-E42,0) | G42: =E42*GeneratorRate | H42: =F42*GovernmentRate | I42: =G42+H42 | J42: =IFERROR(I42/COUNTIFS('Client DB & Bed Mgmt'!$A:$A,A42,'Client DB & Bed Mgmt'!$B:$B,C42,'Client DB & Bed Mgmt'!$D:$D,"<>"),0) | K42: Dorm 1 | L42: Room 1-1 | M42: =COUNTIFS('Client DB & Bed Mgmt'!$A:$A,$K42,'Client DB & Bed Mgmt'!$B:$B,$L42,'Client DB & Bed Mgmt'!$D:$D,"<>") | P42: =IF(N42="","",MAX(N42-O42,0)) | Q42: =IF(O42="","",O42*GeneratorRate) | R42: =IF(P42="","",P42*GovernmentRate) | S42: =IF(N42="","",Q42+R42) | T42: =IF(M42=0,0,S42/M42)
A43: Dorm 1 | B43: 46204 | C43: Room 1-2 | D43: 0 | E43: 0 | F43: =MAX(D43-E43,0) | G43: =E43*GeneratorRate | H43: =F43*GovernmentRate | I43: =G43+H43 | J43: =IFERROR(I43/COUNTIFS('Client DB & Bed Mgmt'!$A:$A,A43,'Client DB & Bed Mgmt'!$B:$B,C43,'Client DB & Bed Mgmt'!$D:$D,"<>"),0) | K43: Dorm 1 | L43: Room 1-2 | M43: =COUNTIFS('Client DB & Bed Mgmt'!$A:$A,$K43,'Client DB & Bed Mgmt'!$B:$B,$L43,'Client DB & Bed Mgmt'!$D:$D,"<>") | P43: =IF(N43="","",MAX(N43-O43,0)) | Q43: =IF(O43="","",O43*GeneratorRate) | R43: =IF(P43="","",P43*GovernmentRate) | S43: =IF(N43="","",Q43+R43) | T43: =IF(M43=0,0,S43/M43)
A44: Dorm 1 | B44: 46204 | C44: Room 1-3 | D44: 0 | E44: 0 | F44: =MAX(D44-E44,0) | G44: =E44*GeneratorRate | H44: =F44*GovernmentRate | I44: =G44+H44 | J44: =IFERROR(I44/COUNTIFS('Client DB & Bed Mgmt'!$A:$A,A44,'Client DB & Bed Mgmt'!$B:$B,C44,'Client DB & Bed Mgmt'!$D:$D,"<>"),0) | K44: Dorm 1 | L44: Room 1-3 | M44: =COUNTIFS('Client DB & Bed Mgmt'!$A:$A,$K44,'Client DB & Bed Mgmt'!$B:$B,$L44,'Client DB & Bed Mgmt'!$D:$D,"<>") | P44: =IF(N44="","",MAX(N44-O44,0)) | Q44: =IF(O44="","",O44*GeneratorRate) | R44: =IF(P44="","",P44*GovernmentRate) | S44: =IF(N44="","",Q44+R44) | T44: =IF(M44=0,0,S44/M44)
A45: Dorm 1 | B45: 46204 | C45: Room 1-4 | D45: 0 | E45: 0 | F45: =MAX(D45-E45,0) | G45: =E45*GeneratorRate | H45: =F45*GovernmentRate | I45: =G45+H45 | J45: =IFERROR(I45/COUNTIFS('Client DB & Bed Mgmt'!$A:$A,A45,'Client DB & Bed Mgmt'!$B:$B,C45,'Client DB & Bed Mgmt'!$D:$D,"<>"),0) | K45: Dorm 1 | L45: Room 1-4 | M45: =COUNTIFS('Client DB & Bed Mgmt'!$A:$A,$K45,'Client DB & Bed Mgmt'!$B:$B,$L45,'Client DB & Bed Mgmt'!$D:$D,"<>") | P45: =IF(N45="","",MAX(N45-O45,0)) | Q45: =IF(O45="","",O45*GeneratorRate) | R45: =IF(P45="","",P45*GovernmentRate) | S45: =IF(N45="","",Q45+R45) | T45: =IF(M45=0,0,S45/M45)
A46: Dorm 1 | B46: 46204 | C46: Room 1-5 | D46: 0 | E46: 0 | F46: =MAX(D46-E46,0) | G46: =E46*GeneratorRate | H46: =F46*GovernmentRate | I46: =G46+H46 | J46: =IFERROR(I46/COUNTIFS('Client DB & Bed Mgmt'!$A:$A,A46,'Client DB & Bed Mgmt'!$B:$B,C46,'Client DB & Bed Mgmt'!$D:$D,"<>"),0) | K46: Dorm 1 | L46: Room 1-5 | M46: =COUNTIFS('Client DB & Bed Mgmt'!$A:$A,$K46,'Client DB & Bed Mgmt'!$B:$B,$L46,'Client DB & Bed Mgmt'!$D:$D,"<>") | P46: =IF(N46="","",MAX(N46-O46,0)) | Q46: =IF(O46="","",O46*GeneratorRate) | R46: =IF(P46="","",P46*GovernmentRate) | S46: =IF(N46="","",Q46+R46) | T46: =IF(M46=0,0,S46/M46)
A47: Dorm 1 | B47: 46204 | C47: Room 1-6 | D47: 0 | E47: 0 | F47: =MAX(D47-E47,0) | G47: =E47*GeneratorRate | H47: =F47*GovernmentRate | I47: =G47+H47 | J47: =IFERROR(I47/COUNTIFS('Client DB & Bed Mgmt'!$A:$A,A47,'Client DB & Bed Mgmt'!$B:$B,C47,'Client DB & Bed Mgmt'!$D:$D,"<>"),0) | K47: Dorm 1 | L47: Room 1-6 | M47: =COUNTIFS('Client DB & Bed Mgmt'!$A:$A,$K47,'Client DB & Bed Mgmt'!$B:$B,$L47,'Client DB & Bed Mgmt'!$D:$D,"<>") | P47: =IF(N47="","",MAX(N47-O47,0)) | Q47: =IF(O47="","",O47*GeneratorRate) | R47: =IF(P47="","",P47*GovernmentRate) | S47: =IF(N47="","",Q47+R47) | T47: =IF(M47=0,0,S47/M47)
A48: Dorm 1 | B48: 46235 | C48: Room 1-1 | D48: 0 | E48: 0 | F48: =MAX(D48-E48,0) | G48: =E48*GeneratorRate | H48: =F48*GovernmentRate | I48: =G48+H48 | J48: =IFERROR(I48/COUNTIFS('Client DB & Bed Mgmt'!$A:$A,A48,'Client DB & Bed Mgmt'!$B:$B,C48,'Client DB & Bed Mgmt'!$D:$D,"<>"),0) | K48: Dorm 1 | L48: Room 1-1 | M48: =COUNTIFS('Client DB & Bed Mgmt'!$A:$A,$K48,'Client DB & Bed Mgmt'!$B:$B,$L48,'Client DB & Bed Mgmt'!$D:$D,"<>") | P48: =IF(N48="","",MAX(N48-O48,0)) | Q48: =IF(O48="","",O48*GeneratorRate) | R48: =IF(P48="","",P48*GovernmentRate) | S48: =IF(N48="","",Q48+R48) | T48: =IF(M48=0,0,S48/M48)
A49: Dorm 1 | B49: 46235 | C49: Room 1-2 | D49: 0 | E49: 0 | F49: =MAX(D49-E49,0) | G49: =E49*GeneratorRate | H49: =F49*GovernmentRate | I49: =G49+H49 | J49: =IFERROR(I49/COUNTIFS('Client DB & Bed Mgmt'!$A:$A,A49,'Client DB & Bed Mgmt'!$B:$B,C49,'Client DB & Bed Mgmt'!$D:$D,"<>"),0) | K49: Dorm 1 | L49: Room 1-2 | M49: =COUNTIFS('Client DB & Bed Mgmt'!$A:$A,$K49,'Client DB & Bed Mgmt'!$B:$B,$L49,'Client DB & Bed Mgmt'!$D:$D,"<>") | P49: =IF(N49="","",MAX(N49-O49,0)) | Q49: =IF(O49="","",O49*GeneratorRate) | R49: =IF(P49="","",P49*GovernmentRate) | S49: =IF(N49="","",Q49+R49) | T49: =IF(M49=0,0,S49/M49)
A50: Dorm 1 | B50: 46235 | C50: Room 1-3 | D50: 0 | E50: 0 | F50: =MAX(D50-E50,0) | G50: =E50*GeneratorRate | H50: =F50*GovernmentRate | I50: =G50+H50 | J50: =IFERROR(I50/COUNTIFS('Client DB & Bed Mgmt'!$A:$A,A50,'Client DB & Bed Mgmt'!$B:$B,C50,'Client DB & Bed Mgmt'!$D:$D,"<>"),0) | K50: Dorm 1 | L50: Room 1-3 | M50: =COUNTIFS('Client DB & Bed Mgmt'!$A:$A,$K50,'Client DB & Bed Mgmt'!$B:$B,$L50,'Client DB & Bed Mgmt'!$D:$D,"<>") | P50: =IF(N50="","",MAX(N50-O50,0)) | Q50: =IF(O50="","",O50*GeneratorRate) | R50: =IF(P50="","",P50*GovernmentRate) | S50: =IF(N50="","",Q50+R50) | T50: =IF(M50=0,0,S50/M50)
A51: Dorm 1 | B51: 46235 | C51: Room 1-4 | D51: 0 | E51: 0 | F51: =MAX(D51-E51,0) | G51: =E51*GeneratorRate | H51: =F51*GovernmentRate | I51: =G51+H51 | J51: =IFERROR(I51/COUNTIFS('Client DB & Bed Mgmt'!$A:$A,A51,'Client DB & Bed Mgmt'!$B:$B,C51,'Client DB & Bed Mgmt'!$D:$D,"<>"),0) | K51: Dorm 1 | L51: Room 1-4 | M51: =COUNTIFS('Client DB & Bed Mgmt'!$A:$A,$K51,'Client DB & Bed Mgmt'!$B:$B,$L51,'Client DB & Bed Mgmt'!$D:$D,"<>") | P51: =IF(N51="","",MAX(N51-O51,0)) | Q51: =IF(O51="","",O51*GeneratorRate) | R51: =IF(P51="","",P51*GovernmentRate) | S51: =IF(N51="","",Q51+R51) | T51: =IF(M51=0,0,S51/M51)
A52: Dorm 1 | B52: 46235 | C52: Room 1-5 | D52: 0 | E52: 0 | F52: =MAX(D52-E52,0) | G52: =E52*GeneratorRate | H52: =F52*GovernmentRate | I52: =G52+H52 | J52: =IFERROR(I52/COUNTIFS('Client DB & Bed Mgmt'!$A:$A,A52,'Client DB & Bed Mgmt'!$B:$B,C52,'Client DB & Bed Mgmt'!$D:$D,"<>"),0) | K52: Dorm 1 | L52: Room 1-5 | M52: =COUNTIFS('Client DB & Bed Mgmt'!$A:$A,$K52,'Client DB & Bed Mgmt'!$B:$B,$L52,'Client DB & Bed Mgmt'!$D:$D,"<>") | P52: =IF(N52="","",MAX(N52-O52,0)) | Q52: =IF(O52="","",O52*GeneratorRate) | R52: =IF(P52="","",P52*GovernmentRate) | S52: =IF(N52="","",Q52+R52) | T52: =IF(M52=0,0,S52/M52)
A53: Dorm 1 | B53: 46235 | C53: Room 1-6 | D53: 0 | E53: 0 | F53: =MAX(D53-E53,0) | G53: =E53*GeneratorRate | H53: =F53*GovernmentRate | I53: =G53+H53 | J53: =IFERROR(I53/COUNTIFS('Client DB & Bed Mgmt'!$A:$A,A53,'Client DB & Bed Mgmt'!$B:$B,C53,'Client DB & Bed Mgmt'!$D:$D,"<>"),0) | K53: Dorm 1 | L53: Room 1-6 | M53: =COUNTIFS('Client DB & Bed Mgmt'!$A:$A,$K53,'Client DB & Bed Mgmt'!$B:$B,$L53,'Client DB & Bed Mgmt'!$D:$D,"<>") | P53: =IF(N53="","",MAX(N53-O53,0)) | Q53: =IF(O53="","",O53*GeneratorRate) | R53: =IF(P53="","",P53*GovernmentRate) | S53: =IF(N53="","",Q53+R53) | T53: =IF(M53=0,0,S53/M53)
... A221: Dorm 3 | B221: 46357 | C221: Room 3-6 | D221: 0 | E221: 0 | F221: =MAX(D221-E221,0) | G221: =E221*GeneratorRate | H221: =F221*GovernmentRate | I221: =G221+H221 | J221: =IFERROR(I221/COUNTIFS('Client DB & Bed Mgmt'!$A:$A,A221,'Client DB & Bed Mgmt'!$B:$B,C221,'Client DB & Bed Mgmt'!$D:$D,"<>"),0) | K221: Dorm 3 | L221: Room 3-6 | M221: =COUNTIFS('Client DB & Bed Mgmt'!$A:$A,$K221,'Client DB & Bed Mgmt'!$B:$B,$L221,'Client DB & Bed Mgmt'!$D:$D,"<>") | P221: =IF(N221="","",MAX(N221-O221,0)) | Q221: =IF(O221="","",O221*GeneratorRate) | R221: =IF(P221="","",P221*GovernmentRate) | S221: =IF(N221="","",Q221+R221) | T221: =IF(M221=0,0,S221/M221)
F222: =IF(D222="","",MAX(D222-E222,0)) | G222: =IF(E222="","",E222*GeneratorRate) | H222: =IF(F222="","",F222*GovernmentRate) | I222: =IF(D222="","",G222+H222) | J222: =IFERROR(I222/COUNTIFS('Client DB & Bed Mgmt'!$A:$A,A222,'Client DB & Bed Mgmt'!$B:$B,C222,'Client DB & Bed Mgmt'!$D:$D,"<>"),0) | M222: =COUNTIFS('Client DB & Bed Mgmt'!$A:$A,$K222,'Client DB & Bed Mgmt'!$B:$B,$L222,'Client DB & Bed Mgmt'!$D:$D,"<>") | P222: =IF(N222="","",MAX(N222-O222,0)) | Q222: =IF(O222="","",O222*GeneratorRate) | R222: =IF(P222="","",P222*GovernmentRate) | S222: =IF(N222="","",Q222+R222) | T222: =IF(M222=0,0,S222/M222)
F223: =IF(D223="","",MAX(D223-E223,0)) | G223: =IF(E223="","",E223*GeneratorRate) | H223: =IF(F223="","",F223*GovernmentRate) | I223: =IF(D223="","",G223+H223) | J223: =IFERROR(I223/COUNTIFS('Client DB & Bed Mgmt'!$A:$A,A223,'Client DB & Bed Mgmt'!$B:$B,C223,'Client DB & Bed Mgmt'!$D:$D,"<>"),0) | M223: =COUNTIFS('Client DB & Bed Mgmt'!$A:$A,$K223,'Client DB & Bed Mgmt'!$B:$B,$L223,'Client DB & Bed Mgmt'!$D:$D,"<>") | P223: =IF(N223="","",MAX(N223-O223,0)) | Q223: =IF(O223="","",O223*GeneratorRate) | R223: =IF(P223="","",P223*GovernmentRate) | S223: =IF(N223="","",Q223+R223) | T223: =IF(M223=0,0,S223/M223)
F224: =IF(D224="","",MAX(D224-E224,0)) | G224: =IF(E224="","",E224*GeneratorRate) | H224: =IF(F224="","",F224*GovernmentRate) | I224: =IF(D224="","",G224+H224) | J224: =IFERROR(I224/COUNTIFS('Client DB & Bed Mgmt'!$A:$A,A224,'Client DB & Bed Mgmt'!$B:$B,C224,'Client DB & Bed Mgmt'!$D:$D,"<>"),0) | M224: =COUNTIFS('Client DB & Bed Mgmt'!$A:$A,$K224,'Client DB & Bed Mgmt'!$B:$B,$L224,'Client DB & Bed Mgmt'!$D:$D,"<>") | P224: =IF(N224="","",MAX(N224-O224,0)) | Q224: =IF(O224="","",O224*GeneratorRate) | R224: =IF(P224="","",P224*GovernmentRate) | S224: =IF(N224="","",Q224+R224) | T224: =IF(M224=0,0,S224/M224)
F225: =IF(D225="","",MAX(D225-E225,0)) | G225: =IF(E225="","",E225*GeneratorRate) | H225: =IF(F225="","",F225*GovernmentRate) | I225: =IF(D225="","",G225+H225) | J225: =IFERROR(I225/COUNTIFS('Client DB & Bed Mgmt'!$A:$A,A225,'Client DB & Bed Mgmt'!$B:$B,C225,'Client DB & Bed Mgmt'!$D:$D,"<>"),0) | M225: =COUNTIFS('Client DB & Bed Mgmt'!$A:$A,$K225,'Client DB & Bed Mgmt'!$B:$B,$L225,'Client DB & Bed Mgmt'!$D:$D,"<>") | P225: =IF(N225="","",MAX(N225-O225,0)) | Q225: =IF(O225="","",O225*GeneratorRate) | R225: =IF(P225="","",P225*GovernmentRate) | S225: =IF(N225="","",Q225+R225) | T225: =IF(M225=0,0,S225/M225)
F226: =IF(D226="","",MAX(D226-E226,0)) | G226: =IF(E226="","",E226*GeneratorRate) | H226: =IF(F226="","",F226*GovernmentRate) | I226: =IF(D226="","",G226+H226) | J226: =IFERROR(I226/COUNTIFS('Client DB & Bed Mgmt'!$A:$A,A226,'Client DB & Bed Mgmt'!$B:$B,C226,'Client DB & Bed Mgmt'!$D:$D,"<>"),0) | M226: =COUNTIFS('Client DB & Bed Mgmt'!$A:$A,$K226,'Client DB & Bed Mgmt'!$B:$B,$L226,'Client DB & Bed Mgmt'!$D:$D,"<>") | P226: =IF(N226="","",MAX(N226-O226,0)) | Q226: =IF(O226="","",O226*GeneratorRate) | R226: =IF(P226="","",P226*GovernmentRate) | S226: =IF(N226="","",Q226+R226) | T226: =IF(M226=0,0,S226/M226)
F227: =IF(D227="","",MAX(D227-E227,0)) | G227: =IF(E227="","",E227*GeneratorRate) | H227: =IF(F227="","",F227*GovernmentRate) | I227: =IF(D227="","",G227+H227) | J227: =IFERROR(I227/COUNTIFS('Client DB & Bed Mgmt'!$A:$A,A227,'Client DB & Bed Mgmt'!$B:$B,C227,'Client DB & Bed Mgmt'!$D:$D,"<>"),0) | M227: =COUNTIFS('Client DB & Bed Mgmt'!$A:$A,$K227,'Client DB & Bed Mgmt'!$B:$B,$L227,'Client DB & Bed Mgmt'!$D:$D,"<>") | P227: =IF(N227="","",MAX(N227-O227,0)) | Q227: =IF(O227="","",O227*GeneratorRate) | R227: =IF(P227="","",P227*GovernmentRate) | S227: =IF(N227="","",Q227+R227) | T227: =IF(M227=0,0,S227/M227)
F228: =IF(D228="","",MAX(D228-E228,0)) | G228: =IF(E228="","",E228*GeneratorRate) | H228: =IF(F228="","",F228*GovernmentRate) | I228: =IF(D228="","",G228+H228) | J228: =IFERROR(I228/COUNTIFS('Client DB & Bed Mgmt'!$A:$A,A228,'Client DB & Bed Mgmt'!$B:$B,C228,'Client DB & Bed Mgmt'!$D:$D,"<>"),0) | M228: =COUNTIFS('Client DB & Bed Mgmt'!$A:$A,$K228,'Client DB & Bed Mgmt'!$B:$B,$L228,'Client DB & Bed Mgmt'!$D:$D,"<>") | P228: =IF(N228="","",MAX(N228-O228,0)) | Q228: =IF(O228="","",O228*GeneratorRate) | R228: =IF(P228="","",P228*GovernmentRate) | S228: =IF(N228="","",Q228+R228) | T228: =IF(M228=0,0,S228/M228)
F229: =IF(D229="","",MAX(D229-E229,0)) | G229: =IF(E229="","",E229*GeneratorRate) | H229: =IF(F229="","",F229*GovernmentRate) | I229: =IF(D229="","",G229+H229) | J229: =IFERROR(I229/COUNTIFS('Client DB & Bed Mgmt'!$A:$A,A229,'Client DB & Bed Mgmt'!$B:$B,C229,'Client DB & Bed Mgmt'!$D:$D,"<>"),0) | M229: =COUNTIFS('Client DB & Bed Mgmt'!$A:$A,$K229,'Client DB & Bed Mgmt'!$B:$B,$L229,'Client DB & Bed Mgmt'!$D:$D,"<>") | P229: =IF(N229="","",MAX(N229-O229,0)) | Q229: =IF(O229="","",O229*GeneratorRate) | R229: =IF(P229="","",P229*GovernmentRate) | S229: =IF(N229="","",Q229+R229) | T229: =IF(M229=0,0,S229/M229)
...

Sheet Invoice Generator
B2: DooRm Invoice
B3: Professional student housing / dormitory billing statement
B5: Lookup By | C5: Client Name | F5: Payment Status | G5: =IFERROR(_xlfn.XLOOKUP($C$6,'Client DB & Bed Mgmt'!$D:$D,'Client DB & Bed Mgmt'!$L:$L,""),"")
B6: Client / Bed Selection | C6: ikr | F6: Due Date | G6: =EOMONTH(C7,0)
B7: Billing Month | C7: =IFERROR(DATE(YEAR($G$12),MONTH($G$12),1),CurrentMonth) | F7: Invoice #
B10: Client Name | C10: =C6 | F10: Phone | G10: =IFERROR(_xlfn.XLOOKUP($C$6,'Client DB & Bed Mgmt'!$D:$D,'Client DB & Bed Mgmt'!$Q:$Q,""),"")
B11: Dorm | C11: =IFERROR(_xlfn.XLOOKUP($C$6,'Client DB & Bed Mgmt'!$D:$D,'Client DB & Bed Mgmt'!$A:$A,""),"") | F11: Contract End | G11: =IFERROR(_xlfn.XLOOKUP($C$6,'Client DB & Bed Mgmt'!$D:$D,'Client DB & Bed Mgmt'!$S:$S,""),"")
B12: Room | C12: =IFERROR(_xlfn.XLOOKUP($C$6,'Client DB & Bed Mgmt'!$D:$D,'Client DB & Bed Mgmt'!$B:$B,""),"") | F12: Move-in Date | G12: =IFERROR(_xlfn.XLOOKUP($C$6,'Client DB & Bed Mgmt'!$D:$D,'Client DB & Bed Mgmt'!$M:$M,""),"")
B13: Bed | C13: =IFERROR(_xlfn.XLOOKUP($C$6,'Client DB & Bed Mgmt'!$D:$D,'Client DB & Bed Mgmt'!$C:$C,""),"") | F13: Move-out Date | G13: =IFERROR(_xlfn.XLOOKUP($C$6,'Client DB & Bed Mgmt'!$D:$D,'Client DB & Bed Mgmt'!$N:$N,""),"")
B14: Billing Month | C14: =$C$7
B17: Charges | H17: Prorata
B18: Base Rent / Loyer Par Personne | G18: =IFERROR(_xlfn.XLOOKUP($C$6,'Client DB & Bed Mgmt'!$D:$D,'Client DB & Bed Mgmt'!$I:$I,0),0) | H18: =G18*$H$24
B19: Electricity Per Person | G19: =IFERROR(_xlfn.XLOOKUP($C$6,'Client DB & Bed Mgmt'!$D:$D,'Client DB & Bed Mgmt'!$J:$J,0),0) | H19: ='Electricity Management'!$AA$6
B20: Common Area Electricity | G20: =IFERROR(_xlfn.XLOOKUP($C$6,'Client DB & Bed Mgmt'!$D:$D,'Client DB & Bed Mgmt'!$K:$K,0),0) | H20: ='Electricity Management'!$AB$6
B21: Fixed Generator Fee | G21: =FixedGeneratorFee | H21: =G21*$H$24
B22: Fixed Government Fee | G22: =FixedGovernmentFee | H22: =G22*$H$24
B24: Calculs visibles: Client DB colonne S = Loyer Par Personne; Electricity colonne J = Electricity Per Personne. | H24: ='Electricity Management'!$Z$6
B25: Total Amount Due | G25: =SUM(G18:G22) | H25: =SUM(H18:H22)
B28: Notes
B29: Payment instructions / client notes

Sheet 12-Month Financial Model
A1: 12-Month Financial Model & Cash Flow
A2: Rolling forecast for revenue, operating expenses, rent, and profitability.
A4: Start Date | B4: 46082
A5: Bed Capacity | B5: =SUM(DormRegistry[Bed Capacity])
A6: Rent Per Bed | B6: =DefaultRentPerBed
A7: Target Occupancy % | B7: =TargetOccupancy
A8: Inflation % | B8: =InflationRate
A9: Generator Rate per kWh | B9: =GeneratorRate
A10: Government Rate per kWh | B10: =GovernmentRate
A13: Month | B13: Dorm Name | C13: Ownership Type | D13: Bed Capacity | E13: Rent Per Bed | F13: Target Occupancy % | G13: Inflation % | H13: Maximum Gross Revenue | I13: Actual Revenue | J13: Target Revenue | K13: Municipality Fees | L13: Building Subscription Fees | M13: Cleaning | N13: Maintenance | O13: Internet | P13: Supplies | Q13: Marketing | R13: Building Rent | S13: Operating Expenses | T13: Net Profit | U13: Net Margin
A14: =EDATE(StartDate,0) | B14: Dorm 1 | C14: =IFERROR(_xlfn.XLOOKUP(B14,DormRegistry[Dorm Name],DormRegistry[Ownership Type]),"") | D14: =IFERROR(_xlfn.XLOOKUP(B14,DormRegistry[Dorm Name],DormRegistry[Bed Capacity]),0) | E14: =$B$6*(1+$B$8)^(YEAR(A14)-YEAR(StartDate)) | F14: =$B$7 | G14: =$B$8 | H14: =D14*E14 | J14: =D14*F14*E14 | K14: 75 | L14: 50 | M14: 150 | N14: 125 | O14: 60 | P14: 80 | Q14: 40 | R14: =IF(C14="Owned",0,2500) | S14: =SUM(K14:R14) | T14: =I14-S14 | U14: =IFERROR(T14/I14,0)
A15: =EDATE(StartDate,0) | B15: Dorm 2 | C15: =IFERROR(_xlfn.XLOOKUP(B15,DormRegistry[Dorm Name],DormRegistry[Ownership Type]),"") | D15: =IFERROR(_xlfn.XLOOKUP(B15,DormRegistry[Dorm Name],DormRegistry[Bed Capacity]),0) | E15: =$B$6*(1+$B$8)^(YEAR(A15)-YEAR(StartDate)) | F15: =$B$7 | G15: =$B$8 | H15: =D15*E15 | J15: =D15*F15*E15 | K15: 75 | L15: 50 | M15: 150 | N15: 125 | O15: 60 | P15: 80 | Q15: 40 | R15: =IF(C15="Owned",0,2500) | S15: =SUM(K15:R15) | T15: =I15-S15 | U15: =IFERROR(T15/I15,0)
A16: =EDATE(StartDate,0) | B16: Dorm 3 | C16: =IFERROR(_xlfn.XLOOKUP(B16,DormRegistry[Dorm Name],DormRegistry[Ownership Type]),"") | D16: =IFERROR(_xlfn.XLOOKUP(B16,DormRegistry[Dorm Name],DormRegistry[Bed Capacity]),0) | E16: =$B$6*(1+$B$8)^(YEAR(A16)-YEAR(StartDate)) | F16: =$B$7 | G16: =$B$8 | H16: =D16*E16 | J16: =D16*F16*E16 | K16: 75 | L16: 50 | M16: 150 | N16: 125 | O16: 60 | P16: 80 | Q16: 40 | R16: =IF(C16="Owned",0,2500) | S16: =SUM(K16:R16) | T16: =I16-S16 | U16: =IFERROR(T16/I16,0)
A17: =EDATE(StartDate,1) | B17: Dorm 1 | C17: =IFERROR(_xlfn.XLOOKUP(B17,DormRegistry[Dorm Name],DormRegistry[Ownership Type]),"") | D17: =IFERROR(_xlfn.XLOOKUP(B17,DormRegistry[Dorm Name],DormRegistry[Bed Capacity]),0) | E17: =$B$6*(1+$B$8)^(YEAR(A17)-YEAR(StartDate)) | F17: =$B$7 | G17: =$B$8 | H17: =D17*E17 | J17: =D17*F17*E17 | K17: 75 | L17: 50 | M17: 150 | N17: 125 | O17: 60 | P17: 80 | Q17: 40 | R17: =IF(C17="Owned",0,2500) | S17: =SUM(K17:R17) | T17: =I17-S17 | U17: =IFERROR(T17/I17,0)
A18: =EDATE(StartDate,1) | B18: Dorm 2 | C18: =IFERROR(_xlfn.XLOOKUP(B18,DormRegistry[Dorm Name],DormRegistry[Ownership Type]),"") | D18: =IFERROR(_xlfn.XLOOKUP(B18,DormRegistry[Dorm Name],DormRegistry[Bed Capacity]),0) | E18: =$B$6*(1+$B$8)^(YEAR(A18)-YEAR(StartDate)) | F18: =$B$7 | G18: =$B$8 | H18: =D18*E18 | J18: =D18*F18*E18 | K18: 75 | L18: 50 | M18: 150 | N18: 125 | O18: 60 | P18: 80 | Q18: 40 | R18: =IF(C18="Owned",0,2500) | S18: =SUM(K18:R18) | T18: =I18-S18 | U18: =IFERROR(T18/I18,0)
